<?xml version="1.0" ?>
<!-- =================================================================================== -->
<!-- |    This document was autogenerated by xacro from duckiebot.urdf.xacro           | -->
<!-- |    EDITING THIS FILE BY HAND IS NOT RECOMMENDED                                 | -->
<!-- =================================================================================== -->
<robot name="duckiebot">
  <!--
    Required arguments are:

        - veh:      Vehicle name (e.g., autobot04)
        - model:    Robot configuration (e.g., DB18)

    -->
  <!-- START: Duckiebot -->
  <!-- START: Duckiebot: DB21X -->
  <!-- ~/footprint is located at the projection of the wheels axis' center on the ground -->
  <link name="david/footprint"/>
  <!-- /base link is attached to the bottom of the bottom plate -->
  <link name="david/base"/>
  <joint name="david_footprint_to_base" type="fixed">
    <parent link="david/footprint"/>
    <child link="david/base"/>
    <origin xyz="0 0 0.042"/>
  </joint>
  <!-- bottom plate -->
  <link name="david/bottom_plate">
    <visual>
      <origin xyz="0 0 -0.003"/>
      <geometry>
        <mesh filename="package://duckietown/urdf/meshes/duckiebot/DB21M/bottom_plate.obj"/>
      </geometry>
    </visual>
  </link>
  <joint name="david_base_to_bottom_plate" type="fixed">
    <parent link="david/base"/>
    <child link="david/bottom_plate"/>
    <origin xyz="0 0 0.003"/>
  </joint>
  <!-- side plate (left) -->
  <link name="david/side_plate_left">
    <visual>
      <geometry>
        <mesh filename="package://duckietown/urdf/meshes/duckiebot/DB21M/side_plate_left.obj"/>
      </geometry>
    </visual>
  </link>
  <joint name="david_bottom_plate_to_side_plate_left" type="fixed">
    <parent link="david/bottom_plate"/>
    <child link="david/side_plate_left"/>
    <origin xyz="-0.001 0.034 0"/>
  </joint>
  <!-- side plate (right) -->
  <link name="david/side_plate_right">
    <visual>
      <geometry>
        <mesh filename="package://duckietown/urdf/meshes/duckiebot/DB21M/side_plate_right.obj"/>
      </geometry>
    </visual>
  </link>
  <joint name="david_bottom_plate_to_side_plate_right" type="fixed">
    <parent link="david/bottom_plate"/>
    <child link="david/side_plate_right"/>
    <origin xyz="-0.001 -0.034 0"/>
  </joint>
  <!-- top plate -->
  <link name="david/top_plate">
    <visual>
      <origin xyz="0 0 -0.003"/>
      <geometry>
        <mesh filename="package://duckietown/urdf/meshes/duckiebot/DB21M/top_plate.obj"/>
      </geometry>
    </visual>
  </link>
  <joint name="david_bottom_plate_to_top_plate" type="fixed">
    <parent link="david/bottom_plate"/>
    <child link="david/top_plate"/>
    <origin xyz="0 0 0.031"/>
  </joint>
  <!-- side cover (left) -->
  <link name="david/side_cover_left">
    <visual>
      <geometry>
        <mesh filename="package://duckietown/urdf/meshes/duckiebot/DB21M/side_cover_left.obj"/>
      </geometry>
    </visual>
  </link>
  <joint name="david_top_plate_to_side_cover_left" type="fixed">
    <parent link="david/top_plate"/>
    <child link="david/side_cover_left"/>
    <origin xyz="-0.001 0.042 0"/>
  </joint>
  <!-- side cover (right) -->
  <link name="david/side_cover_right">
    <visual>
      <geometry>
        <mesh filename="package://duckietown/urdf/meshes/duckiebot/DB21M/side_cover_right.obj"/>
      </geometry>
    </visual>
  </link>
  <joint name="david_top_plate_to_side_cover_right" type="fixed">
    <parent link="david/top_plate"/>
    <child link="david/side_cover_right"/>
    <origin xyz="-0.001 -0.042 0"/>
  </joint>
  <!-- interaction plate -->
  <link name="david/interaction_plate">
    <visual>
      <origin xyz="0 0 -0.003"/>
      <geometry>
        <mesh filename="package://duckietown/urdf/meshes/duckiebot/DB21M/interaction_plate.obj"/>
      </geometry>
    </visual>
  </link>
  <joint name="david_top_plate_to_interaction_plate" type="fixed">
    <parent link="david/top_plate"/>
    <child link="david/interaction_plate"/>
    <origin xyz="0 0 0.044"/>
  </joint>
  <!-- hat plate -->
  <link name="david/hat_support">
    <visual>
      <geometry>
        <mesh filename="package://duckietown/urdf/meshes/duckiebot/DB21M/hat_support.obj"/>
      </geometry>
    </visual>
  </link>
  <joint name="david_top_plate_to_hat_support" type="fixed">
    <parent link="david/top_plate"/>
    <child link="david/hat_support"/>
    <origin xyz="-0.12 0 0.01"/>
  </joint>
  <!-- left motor -->
  <link name="david/left_motor">
    <visual>
      <geometry>
        <mesh filename="package://duckietown/urdf/meshes/duckiebot/DB21M/motor.obj"/>
      </geometry>
    </visual>
  </link>
  <joint name="david_base_to_left_motor" type="fixed">
    <parent link="david/base"/>
    <child link="david/left_motor"/>
    <origin xyz="0 0.026 -0.01"/>
  </joint>
  <!-- right motor -->
  <link name="david/right_motor">
    <visual>
      <geometry>
        <mesh filename="package://duckietown/urdf/meshes/duckiebot/DB21M/motor.obj"/>
      </geometry>
    </visual>
  </link>
  <joint name="david_base_to_right_motor" type="fixed">
    <parent link="david/base"/>
    <child link="david/right_motor"/>
    <origin xyz="0 -0.026 -0.01"/>
  </joint>
  <!-- left wheel -->
  <link name="david/left_wheel_axis"/>
  <joint name="david_left_motor_to_left_wheel" type="fixed">
    <parent link="david/left_motor"/>
    <child link="david/left_wheel_axis"/>
    <origin xyz="0 0.015 0"/>
  </joint>
  <link name="david/left_wheel">
    <visual>
      <origin rpy="0 0 3.141592653589793"/>
      <geometry>
        <mesh filename="package://duckietown/urdf/meshes/duckiebot/DB18/wheel.dae"/>
      </geometry>
    </visual>
  </link>
  <joint name="david_left_wheel_axis_to_left_wheel" type="continuous">
    <parent link="david/left_wheel_axis"/>
    <child link="david/left_wheel"/>
    <axis xyz="0 1 0"/>
  </joint>
  <!-- right wheel -->
  <link name="david/right_wheel_axis"/>
  <joint name="david_right_motor_to_right_wheel" type="fixed">
    <parent link="david/right_motor"/>
    <child link="david/right_wheel_axis"/>
    <origin xyz="0 -0.015 0"/>
  </joint>
  <link name="david/right_wheel">
    <visual>
      <geometry>
        <mesh filename="package://duckietown/urdf/meshes/duckiebot/DB18/wheel.dae"/>
      </geometry>
    </visual>
  </link>
  <joint name="david_right_wheel_axis_to_right_wheel" type="continuous">
    <parent link="david/right_wheel_axis"/>
    <child link="david/right_wheel"/>
    <axis xyz="0 1 0"/>
  </joint>
  <!-- caster wheel -->
  <link name="david/caster_wheel">
    <visual>
      <geometry>
        <mesh filename="package://duckietown/urdf/meshes/duckiebot/DB18/caster_wheel.dae"/>
      </geometry>
    </visual>
  </link>
  <joint name="david_bottom_plate_to_caster_wheel" type="fixed">
    <parent link="david/bottom_plate"/>
    <child link="david/caster_wheel"/>
    <origin xyz="-0.085 0 -0.003"/>
  </joint>
  <!-- front bumper -->
  <link name="david/front_bumper">
    <visual>
      <geometry>
        <mesh filename="package://duckietown/urdf/meshes/duckiebot/DB21M/front_bumper.obj"/>
      </geometry>
    </visual>
  </link>
  <joint name="david_top_plate_to_front_bumper" type="fixed">
    <parent link="david/top_plate"/>
    <child link="david/front_bumper"/>
    <origin xyz="0.057 0 0"/>
  </joint>
  <!-- back bumper -->
  <link name="david/back_bumper">
    <visual>
      <geometry>
        <mesh filename="package://duckietown/urdf/meshes/duckiebot/DB21M/back_bumper.obj"/>
      </geometry>
    </visual>
  </link>
  <joint name="david_top_plate_to_back_bumper" type="fixed">
    <parent link="david/top_plate"/>
    <child link="david/back_bumper"/>
    <origin rpy="0 0 3.141592653589793" xyz="-0.113 0 0"/>
  </joint>
  <!-- tag mount -->
  <link name="david/tag_mount"/>
  <joint name="david_interaction_plate_to_tag_mount" type="fixed">
    <parent link="david/interaction_plate"/>
    <child link="david/tag_mount"/>
    <origin rpy="3.141592653589793 0 -1.5707963267948966" xyz="-0.084 0 0"/>
  </joint>
  <!-- camera mount -->
  <link name="david/camera_mount">
    <visual>
      <geometry>
        <mesh filename="package://duckietown/urdf/meshes/duckiebot/DB21M/camera_mount.obj"/>
      </geometry>
    </visual>
  </link>
  <joint name="david_top_plate_to_camera_mount" type="fixed">
    <parent link="david/top_plate"/>
    <child link="david/camera_mount"/>
    <origin xyz="0.058 0 0"/>
  </joint>
  <!-- camera support -->
  <link name="david/camera_support"/>
  <joint name="david_camera_mount_to_camera_support" type="fixed">
    <parent link="david/camera_mount"/>
    <child link="david/camera_support"/>
    <origin xyz="0.006 0 0.028"/>
  </joint>
  <!-- camera frame -->
  <link name="david/camera_frame">
    <visual>
      <geometry>
        <mesh filename="package://duckietown/urdf/meshes/duckiebot/DB18/fish_eye_camera.dae"/>
      </geometry>
    </visual>
  </link>
  <!-- TODO: this should not be fixed (floating), rotation should be computed from the extrinsics calibration of the camera -->
  <joint name="david_camera_support_to_camera_frame" type="fixed">
    <parent link="david/camera_support"/>
    <child link="david/camera_frame"/>
    <origin rpy="0 0.26 0"/>
  </joint>
  <!-- camera optical frame -->
  <link name="david/camera_optical_frame"/>
  <joint name="david_camera_frame_to_camera_optical_frame" type="fixed">
    <parent link="david/camera_frame"/>
    <child link="david/camera_optical_frame"/>
    <origin rpy="-1.5707963267948966 0 -1.5707963267948966" xyz="0.017 0 0"/>
  </joint>
  <!-- END: Duckiebot: DB21X -->
  <!-- END: Duckiebot -->
</robot>

